---
title: Try... Catch... Istruzione finally (Visual Basic) | Documenti di Microsoft
ms.date: 2015-07-20
ms.prod: .net
ms.reviewer: 
ms.suite: 
ms.technology:
- devlang-visual-basic
ms.topic: article
f1_keywords:
- vb.Try...Catch...Finally
- vb.when
- vb.Finally
- vb.Catch
- vb.Try
dev_langs:
- VB
helpviewer_keywords:
- Try...Catch...Finally statements
- Try statement
- try-catch exception handling, Try...Catch...Finally statements
- error handling, while running code
- Try statement, Try...Catch...Finally
- Finally keyword [Visual Basic], Try...Catch...Finally
- Catch statement
- When keyword
- Visual Basic code, handling errors while running
- structured exception handling, Try...Catch...Finally statements
ms.assetid: d6488026-ccb3-42b8-a810-0d97b9d6472b
caps.latest.revision: 69
author: dotnet-bot
ms.author: dotnetcontent
translation.priority.ht:
- cs-cz
- de-de
- es-es
- fr-fr
- it-it
- ja-jp
- ko-kr
- pl-pl
- pt-br
- ru-ru
- tr-tr
- zh-cn
- zh-tw
ms.translationtype: Machine Translation
ms.sourcegitcommit: 9f5b8ebb69c9206ff90b05e748c64d29d82f7a16
ms.openlocfilehash: 590fcd4aa0a6951b63ad12a7d019c09dba1ff38f
ms.contentlocale: it-it
ms.lasthandoff: 04/12/2017

---
# <a name="trycatchfinally-statement-visual-basic"></a><span data-ttu-id="eee9d-102">Istruzione Try...Catch...Finally (Visual Basic)</span><span class="sxs-lookup"><span data-stu-id="eee9d-102">Try...Catch...Finally Statement (Visual Basic)</span></span>
<span data-ttu-id="eee9d-103">Fornisce un modo per gestire alcuni o tutti i possibili errori che potrebbero verificarsi in un determinato blocco di codice, codice in esecuzione.</span><span class="sxs-lookup"><span data-stu-id="eee9d-103">Provides a way to handle some or all possible errors that may occur in a given block of code, while still running code.</span></span>  
  
## <a name="syntax"></a><span data-ttu-id="eee9d-104">Sintassi</span><span class="sxs-lookup"><span data-stu-id="eee9d-104">Syntax</span></span>  
  
```  
Try  
    [ tryStatements ]  
    [ Exit Try ]  
[ Catch [ exception [ As type ] ] [ When expression ]  
    [ catchStatements ]  
    [ Exit Try ] ]  
[ Catch ... ]  
[ Finally  
    [ finallyStatements ] ]  
End Try  
```  
  
## <a name="parts"></a><span data-ttu-id="eee9d-105">Parti</span><span class="sxs-lookup"><span data-stu-id="eee9d-105">Parts</span></span>  
  
|<span data-ttu-id="eee9d-106">Termine</span><span class="sxs-lookup"><span data-stu-id="eee9d-106">Term</span></span>|<span data-ttu-id="eee9d-107">Definizione</span><span class="sxs-lookup"><span data-stu-id="eee9d-107">Definition</span></span>|  
|---|---|  
|`tryStatements`|<span data-ttu-id="eee9d-108">Facoltativo.</span><span class="sxs-lookup"><span data-stu-id="eee9d-108">Optional.</span></span> <span data-ttu-id="eee9d-109">Una o più istruzioni in cui può verificarsi un errore.</span><span class="sxs-lookup"><span data-stu-id="eee9d-109">Statement(s) where an error can occur.</span></span> <span data-ttu-id="eee9d-110">Può essere un'istruzione composta.</span><span class="sxs-lookup"><span data-stu-id="eee9d-110">Can be a compound statement.</span></span>|  
|`Catch`|<span data-ttu-id="eee9d-111">Facoltativo.</span><span class="sxs-lookup"><span data-stu-id="eee9d-111">Optional.</span></span> <span data-ttu-id="eee9d-112">Più `Catch` blocchi consentiti.</span><span class="sxs-lookup"><span data-stu-id="eee9d-112">Multiple `Catch` blocks permitted.</span></span> <span data-ttu-id="eee9d-113">Se si verifica un'eccezione durante l'elaborazione di `Try` blocco, ogni `Catch` istruzione verrà esaminata in ordine testuale per stabilire se gestisce l'eccezione, con `exception` che rappresenta l'eccezione che è stata generata.</span><span class="sxs-lookup"><span data-stu-id="eee9d-113">If an exception occurs when processing the `Try` block, each `Catch` statement is examined in textual order to determine whether it handles the exception, with `exception` representing the exception that has been thrown.</span></span>|  
|`exception`|<span data-ttu-id="eee9d-114">Facoltativo.</span><span class="sxs-lookup"><span data-stu-id="eee9d-114">Optional.</span></span> <span data-ttu-id="eee9d-115">Qualsiasi nome di variabile.</span><span class="sxs-lookup"><span data-stu-id="eee9d-115">Any variable name.</span></span> <span data-ttu-id="eee9d-116">Il valore iniziale di `exception` corrisponde al valore dell'errore generato.</span><span class="sxs-lookup"><span data-stu-id="eee9d-116">The initial value of `exception` is the value of the thrown error.</span></span> <span data-ttu-id="eee9d-117">Utilizzato con `Catch` per specificare l'errore rilevato.</span><span class="sxs-lookup"><span data-stu-id="eee9d-117">Used with `Catch` to specify the error caught.</span></span> <span data-ttu-id="eee9d-118">Se omesso, il `Catch` istruzione genera un'eccezione.</span><span class="sxs-lookup"><span data-stu-id="eee9d-118">If omitted, the `Catch` statement catches any exception.</span></span>|  
|`type`|<span data-ttu-id="eee9d-119">Facoltativo.</span><span class="sxs-lookup"><span data-stu-id="eee9d-119">Optional.</span></span> <span data-ttu-id="eee9d-120">Specifica il tipo di filtro di classe.</span><span class="sxs-lookup"><span data-stu-id="eee9d-120">Specifies the type of class filter.</span></span> <span data-ttu-id="eee9d-121">Se il valore di `exception` è del tipo specificato da `type` o di un tipo derivato, l'identificatore viene associato all'oggetto eccezione.</span><span class="sxs-lookup"><span data-stu-id="eee9d-121">If the value of `exception` is of the type specified by `type` or of a derived type, the identifier becomes bound to the exception object.</span></span>|  
|`When`|<span data-ttu-id="eee9d-122">Facoltativo.</span><span class="sxs-lookup"><span data-stu-id="eee9d-122">Optional.</span></span> <span data-ttu-id="eee9d-123">Oggetto `Catch` istruzione con un `When` clausola intercetta le eccezioni solo quando `expression` restituisce `True`.</span><span class="sxs-lookup"><span data-stu-id="eee9d-123">A `Catch` statement with a `When` clause catches exceptions only when `expression` evaluates to `True`.</span></span> <span data-ttu-id="eee9d-124">Oggetto `When` clausola viene applicata solo dopo avere selezionato il tipo di eccezione, e `expression` possono fare riferimento a un identificatore che rappresenta l'eccezione.</span><span class="sxs-lookup"><span data-stu-id="eee9d-124">A `When` clause is applied only after checking the type of the exception, and `expression` may refer to the identifier representing the exception.</span></span>|  
|`expression`|<span data-ttu-id="eee9d-125">Facoltativo.</span><span class="sxs-lookup"><span data-stu-id="eee9d-125">Optional.</span></span> <span data-ttu-id="eee9d-126">Deve essere convertibile in modo implicito in `Boolean`.</span><span class="sxs-lookup"><span data-stu-id="eee9d-126">Must be implicitly convertible to `Boolean`.</span></span> <span data-ttu-id="eee9d-127">Qualsiasi espressione che descrive un filtro generico.</span><span class="sxs-lookup"><span data-stu-id="eee9d-127">Any expression that describes a generic filter.</span></span> <span data-ttu-id="eee9d-128">In genere utilizzato per filtrare in base al numero di errore.</span><span class="sxs-lookup"><span data-stu-id="eee9d-128">Typically used to filter by error number.</span></span> <span data-ttu-id="eee9d-129">Utilizzato con `When` (parola chiave) per specificare le circostanze in cui viene rilevato l'errore.</span><span class="sxs-lookup"><span data-stu-id="eee9d-129">Used with `When` keyword to specify circumstances under which the error is caught.</span></span>|  
|`catchStatements`|<span data-ttu-id="eee9d-130">Facoltativo.</span><span class="sxs-lookup"><span data-stu-id="eee9d-130">Optional.</span></span> <span data-ttu-id="eee9d-131">Istruzioni per gestire gli errori che si verificano nel blocco `Try` blocco.</span><span class="sxs-lookup"><span data-stu-id="eee9d-131">Statement(s) to handle errors that occur in the associated `Try` block.</span></span> <span data-ttu-id="eee9d-132">Può essere un'istruzione composta.</span><span class="sxs-lookup"><span data-stu-id="eee9d-132">Can be a compound statement.</span></span>|  
|`Exit Try`|<span data-ttu-id="eee9d-133">Facoltativo.</span><span class="sxs-lookup"><span data-stu-id="eee9d-133">Optional.</span></span> <span data-ttu-id="eee9d-134">Parola chiave che viene interrotta la `Try...Catch...Finally` struttura.</span><span class="sxs-lookup"><span data-stu-id="eee9d-134">Keyword that breaks out of the `Try...Catch...Finally` structure.</span></span> <span data-ttu-id="eee9d-135">Con il codice immediatamente dopo l'esecuzione riprende il `End Try` istruzione.</span><span class="sxs-lookup"><span data-stu-id="eee9d-135">Execution resumes with the code immediately following the `End Try` statement.</span></span> <span data-ttu-id="eee9d-136">Il `Finally` verrà eseguita l'istruzione.</span><span class="sxs-lookup"><span data-stu-id="eee9d-136">The `Finally` statement will still be executed.</span></span> <span data-ttu-id="eee9d-137">Non è consentito in `Finally` blocchi.</span><span class="sxs-lookup"><span data-stu-id="eee9d-137">Not allowed in `Finally` blocks.</span></span>|  
|`Finally`|<span data-ttu-id="eee9d-138">Facoltativo.</span><span class="sxs-lookup"><span data-stu-id="eee9d-138">Optional.</span></span> <span data-ttu-id="eee9d-139">Oggetto `Finally` blocco viene eseguito quando l'esecuzione lascia qualsiasi parte di `Try...Catch` istruzione.</span><span class="sxs-lookup"><span data-stu-id="eee9d-139">A `Finally` block is always executed when execution leaves any part of the `Try...Catch` statement.</span></span>|  
|`finallyStatements`|<span data-ttu-id="eee9d-140">Facoltativo.</span><span class="sxs-lookup"><span data-stu-id="eee9d-140">Optional.</span></span> <span data-ttu-id="eee9d-141">Una o più istruzioni che vengono eseguite dopo ogni altra elaborazione di errore.</span><span class="sxs-lookup"><span data-stu-id="eee9d-141">Statement(s) that are executed after all other error processing has occurred.</span></span>|  
|`End Try`|<span data-ttu-id="eee9d-142">Termina la `Try...Catch...Finally` struttura.</span><span class="sxs-lookup"><span data-stu-id="eee9d-142">Terminates the `Try...Catch...Finally` structure.</span></span>|  
  
## <a name="remarks"></a><span data-ttu-id="eee9d-143">Note</span><span class="sxs-lookup"><span data-stu-id="eee9d-143">Remarks</span></span>  
 <span data-ttu-id="eee9d-144">Se si prevede che una particolare eccezione potrebbe verificarsi durante una particolare sezione di codice, inserire il codice in un `Try` blocco e utilizzare un `Catch` blocco per mantenere il controllo e gestire l'eccezione, se si verifica.</span><span class="sxs-lookup"><span data-stu-id="eee9d-144">If you expect that a particular exception might occur during a particular section of code, put the code in a `Try` block and use a `Catch` block to retain control and handle the exception if it occurs.</span></span>  
  
 <span data-ttu-id="eee9d-145">Oggetto `Try…Catch` istruzione costituita da un `Try` blocco seguito da uno o più `Catch` clausole che specificano i gestori per diverse eccezioni.</span><span class="sxs-lookup"><span data-stu-id="eee9d-145">A `Try…Catch` statement consists of a `Try` block followed by one or more `Catch` clauses, which specify handlers for various exceptions.</span></span> <span data-ttu-id="eee9d-146">Quando viene generata un'eccezione un `Try` blocco, [!INCLUDE[vbprvb](../../../csharp/programming-guide/concepts/linq/includes/vbprvb_md.md)] Cerca il `Catch` istruzione che gestisce l'eccezione.</span><span class="sxs-lookup"><span data-stu-id="eee9d-146">When an exception is thrown in a `Try` block, [!INCLUDE[vbprvb](../../../csharp/programming-guide/concepts/linq/includes/vbprvb_md.md)] looks for the `Catch` statement that handles the exception.</span></span> <span data-ttu-id="eee9d-147">Se un corrispondente `Catch` istruzione non viene trovata, [!INCLUDE[vbprvb](../../../csharp/programming-guide/concepts/linq/includes/vbprvb_md.md)] esamina il metodo che ha chiamato il metodo corrente, e così via lungo lo stack di chiamate.</span><span class="sxs-lookup"><span data-stu-id="eee9d-147">If a matching `Catch` statement is not found, [!INCLUDE[vbprvb](../../../csharp/programming-guide/concepts/linq/includes/vbprvb_md.md)] examines the method that called the current method, and so on up the call stack.</span></span> <span data-ttu-id="eee9d-148">Se non `Catch` blocco viene trovato, [!INCLUDE[vbprvb](../../../csharp/programming-guide/concepts/linq/includes/vbprvb_md.md)] Visualizza un messaggio di eccezione non gestita all'utente e interrompe l'esecuzione del programma.</span><span class="sxs-lookup"><span data-stu-id="eee9d-148">If no `Catch` block is found, [!INCLUDE[vbprvb](../../../csharp/programming-guide/concepts/linq/includes/vbprvb_md.md)] displays an unhandled exception message to the user and stops execution of the program.</span></span>  
  
 <span data-ttu-id="eee9d-149">È possibile utilizzare più `Catch` istruzione in un `Try…Catch` istruzione.</span><span class="sxs-lookup"><span data-stu-id="eee9d-149">You can use more than one `Catch` statement in a `Try…Catch` statement.</span></span> <span data-ttu-id="eee9d-150">In tal caso, l'ordine dei `Catch` clausole è importante in quanto vengono esaminate nell'ordine.</span><span class="sxs-lookup"><span data-stu-id="eee9d-150">If you do this, the order of the `Catch` clauses is significant because they are examined in order.</span></span> <span data-ttu-id="eee9d-151">Intercettare le eccezioni più specifiche prima di quelle meno specifiche.</span><span class="sxs-lookup"><span data-stu-id="eee9d-151">Catch the more specific exceptions before the less specific ones.</span></span>  
  
 <span data-ttu-id="eee9d-152">Nell'esempio `Catch` condizioni dell'istruzione sono quelle meno specifiche e intercetterà tutte le eccezioni che derivano dalla <xref:System.Exception>classe.</xref:System.Exception></span><span class="sxs-lookup"><span data-stu-id="eee9d-152">The following `Catch` statement conditions are the least specific, and will catch all exceptions that derive from the <xref:System.Exception> class.</span></span> <span data-ttu-id="eee9d-153">È in genere necessario utilizzare una di queste variazioni come l'ultima `Catch` blocco il `Try...Catch...Finally` struttura, dopo l'intercettazione si prevede che tutte le eccezioni specifiche.</span><span class="sxs-lookup"><span data-stu-id="eee9d-153">You should ordinarily use one of these variations as the last `Catch` block in the `Try...Catch...Finally` structure, after catching all the specific exceptions you expect.</span></span> <span data-ttu-id="eee9d-154">Flusso di controllo non può mai raggiungere un `Catch` blocco che segue una di queste variazioni.</span><span class="sxs-lookup"><span data-stu-id="eee9d-154">Control flow can never reach a `Catch` block that follows either of these variations.</span></span>  
  
-   <span data-ttu-id="eee9d-155">Il `type` è `Exception`, ad esempio:`Catch ex As Exception`</span><span class="sxs-lookup"><span data-stu-id="eee9d-155">The `type` is `Exception`, for example: `Catch ex As Exception`</span></span>  
  
-   <span data-ttu-id="eee9d-156">L'istruzione non ha alcun `exception` variabile, ad esempio:`Catch`</span><span class="sxs-lookup"><span data-stu-id="eee9d-156">The statement has no `exception` variable, for example: `Catch`</span></span>  
  
 <span data-ttu-id="eee9d-157">Quando un `Try…Catch…Finally` nidificata in un'altra istruzione `Try` blocco, [!INCLUDE[vbprvb](../../../csharp/programming-guide/concepts/linq/includes/vbprvb_md.md)] innanzitutto esaminare ogni `Catch` istruzione nella parte più interna `Try` blocco.</span><span class="sxs-lookup"><span data-stu-id="eee9d-157">When a `Try…Catch…Finally` statement is nested in another `Try` block, [!INCLUDE[vbprvb](../../../csharp/programming-guide/concepts/linq/includes/vbprvb_md.md)] first examines each `Catch` statement in the innermost `Try` block.</span></span> <span data-ttu-id="eee9d-158">Se nessuna corrispondenza `Catch` istruzione è stata trovata, la ricerca procede con la `Catch` istruzioni di esterna `Try…Catch…Finally` blocco.</span><span class="sxs-lookup"><span data-stu-id="eee9d-158">If no matching `Catch` statement is found, the search proceeds to the `Catch` statements of the outer `Try…Catch…Finally` block.</span></span>  
  
 <span data-ttu-id="eee9d-159">Le variabili locali di un `Try` blocco non sono disponibili in un `Catch` bloccarsi, in quanto rappresentano blocchi separati.</span><span class="sxs-lookup"><span data-stu-id="eee9d-159">Local variables from a `Try` block are not available in a `Catch` block because they are separate blocks.</span></span> <span data-ttu-id="eee9d-160">Se si desidera utilizzare una variabile in più di un blocco, dichiarare la variabile all'esterno di `Try...Catch...Finally` struttura.</span><span class="sxs-lookup"><span data-stu-id="eee9d-160">If you want to use a variable in more than one block, declare the variable outside the `Try...Catch...Finally` structure.</span></span>  
  
> [!TIP]
>  <span data-ttu-id="eee9d-161">La `Try…Catch…Finally` informativa è disponibile come frammento di codice IntelliSense.</span><span class="sxs-lookup"><span data-stu-id="eee9d-161">The `Try…Catch…Finally` statement is available as an IntelliSense code snippet.</span></span> <span data-ttu-id="eee9d-162">In Gestione frammenti di codice, espandere **modelli di codice - se, per ognuno, Try Catch, proprietà, e così via**e quindi **Error Handling (eccezioni)**.</span><span class="sxs-lookup"><span data-stu-id="eee9d-162">In the Code Snippets Manager, expand **Code Patterns - If, For Each, Try Catch, Property, etc**, and then **Error Handling (Exceptions)**.</span></span> <span data-ttu-id="eee9d-163">Per altre informazioni, vedere [Code Snippets](https://docs.microsoft.com/visualstudio/ide/code-snippets) (Frammenti di codice).</span><span class="sxs-lookup"><span data-stu-id="eee9d-163">For more information, see [Code Snippets](https://docs.microsoft.com/visualstudio/ide/code-snippets).</span></span>  
  
## <a name="finally-block"></a><span data-ttu-id="eee9d-164">Blocco finally</span><span class="sxs-lookup"><span data-stu-id="eee9d-164">Finally Block</span></span>  
 <span data-ttu-id="eee9d-165">Se si dispone di uno o più istruzioni da eseguire prima di chiudere il `Try` struttura, utilizzare un `Finally` blocco.</span><span class="sxs-lookup"><span data-stu-id="eee9d-165">If you have one or more statements that must run before you exit the `Try` structure, use a `Finally` block.</span></span> <span data-ttu-id="eee9d-166">Il controllo passa al `Finally` blocco appena prima di passare fuori il `Try…Catch` struttura.</span><span class="sxs-lookup"><span data-stu-id="eee9d-166">Control passes to the `Finally` block just before it passes out of the `Try…Catch` structure.</span></span> <span data-ttu-id="eee9d-167">Questo vale anche se si verifica un'eccezione in un punto qualsiasi all'interno di `Try` struttura.</span><span class="sxs-lookup"><span data-stu-id="eee9d-167">This is true even if an exception occurs anywhere inside the `Try` structure.</span></span>  
  
 <span data-ttu-id="eee9d-168">Oggetto `Finally` blocco è utile per eseguire qualsiasi codice che deve eseguire anche se si verifica un'eccezione.</span><span class="sxs-lookup"><span data-stu-id="eee9d-168">A `Finally` block is useful for running any code that must execute even if there is an exception.</span></span> <span data-ttu-id="eee9d-169">Il controllo viene passato per il `Finally` blocco indipendentemente da come la `Try...Catch` uscita dal blocco.</span><span class="sxs-lookup"><span data-stu-id="eee9d-169">Control is passed to the `Finally` block regardless of how the `Try...Catch` block exits.</span></span>  
  
 <span data-ttu-id="eee9d-170">Il codice in un `Finally` blocco viene eseguito anche se il codice rileva un `Return` istruzione in un `Try` o `Catch` blocco.</span><span class="sxs-lookup"><span data-stu-id="eee9d-170">The code in a `Finally` block runs even if your code encounters a `Return` statement in a `Try` or `Catch` block.</span></span> <span data-ttu-id="eee9d-171">Il controllo viene passato da un `Try` o `Catch` blocco per il corrispondente `Finally` blocco nei casi seguenti:</span><span class="sxs-lookup"><span data-stu-id="eee9d-171">Control does not pass from a `Try` or `Catch` block to the corresponding `Finally` block in the following cases:</span></span>  
  
-   <span data-ttu-id="eee9d-172">Un [istruzione End](../../../visual-basic/language-reference/statements/end-statement.md) viene rilevata nel `Try` o `Catch` blocco.</span><span class="sxs-lookup"><span data-stu-id="eee9d-172">An [End Statement](../../../visual-basic/language-reference/statements/end-statement.md) is encountered in the `Try` or `Catch` block.</span></span>  
  
-   <span data-ttu-id="eee9d-173">Oggetto <xref:System.StackOverflowException>viene generata nel `Try` o `Catch` blocco.</xref:System.StackOverflowException></span><span class="sxs-lookup"><span data-stu-id="eee9d-173">A <xref:System.StackOverflowException> is thrown in the `Try` or `Catch` block.</span></span>  
  
 <span data-ttu-id="eee9d-174">Non è valido per trasferire in modo esplicito l'esecuzione in un `Finally` blocco.</span><span class="sxs-lookup"><span data-stu-id="eee9d-174">It is not valid to explicitly transfer execution into a `Finally` block.</span></span> <span data-ttu-id="eee9d-175">Trasferimento di esecuzione all'esterno di un `Finally` blocco non è valido, ad eccezione di un'eccezione.</span><span class="sxs-lookup"><span data-stu-id="eee9d-175">Transferring execution out of a `Finally` block is not valid, except through an exception.</span></span>  
  
 <span data-ttu-id="eee9d-176">Se un `Try` istruzione non contiene almeno un `Catch` blocco, deve contenere un `Finally` blocco.</span><span class="sxs-lookup"><span data-stu-id="eee9d-176">If a `Try` statement does not contain at least one `Catch` block, it must contain a `Finally` block.</span></span>  
  
> [!TIP]
>  <span data-ttu-id="eee9d-177">Se non è necessario rilevare eccezioni specifiche, il `Using` istruzione si comporta come un `Try…Finally` blocco e garantisce l'eliminazione delle risorse, indipendentemente dalla modalità di uscita dal blocco.</span><span class="sxs-lookup"><span data-stu-id="eee9d-177">If you do not have to catch specific exceptions, the `Using` statement behaves like a `Try…Finally` block, and guarantees disposal of the resources, regardless of how you exit the block.</span></span> <span data-ttu-id="eee9d-178">Ciò è vero anche con un'eccezione non gestita.</span><span class="sxs-lookup"><span data-stu-id="eee9d-178">This is true even with an unhandled exception.</span></span> <span data-ttu-id="eee9d-179">Per ulteriori informazioni, vedere [istruzione Using](../../../visual-basic/language-reference/statements/using-statement.md).</span><span class="sxs-lookup"><span data-stu-id="eee9d-179">For more information, see [Using Statement](../../../visual-basic/language-reference/statements/using-statement.md).</span></span>  
  
## <a name="exception-argument"></a><span data-ttu-id="eee9d-180">Argomento Exception</span><span class="sxs-lookup"><span data-stu-id="eee9d-180">Exception Argument</span></span>  
 <span data-ttu-id="eee9d-181">Il `Catch` blocco `exception` argomento è un'istanza della <xref:System.Exception>classe o una classe che deriva dalla `Exception` classe</xref:System.Exception></span><span class="sxs-lookup"><span data-stu-id="eee9d-181">The `Catch` block `exception` argument is an instance of the <xref:System.Exception> class or a class that derives from the `Exception` class.</span></span> <span data-ttu-id="eee9d-182">Il `Exception` istanza della classe corrisponde all'errore che si è verificato durante il `Try` blocco.</span><span class="sxs-lookup"><span data-stu-id="eee9d-182">The `Exception` class instance corresponds to the error that occurred in the `Try` block.</span></span>  
  
 <span data-ttu-id="eee9d-183">Le proprietà del `Exception` oggetto servono a identificare la causa e la posizione di un'eccezione.</span><span class="sxs-lookup"><span data-stu-id="eee9d-183">The properties of the `Exception` object help to identify the cause and location of an exception.</span></span> <span data-ttu-id="eee9d-184">Ad esempio, la <xref:System.Exception.StackTrace%2A>proprietà sono elencati i metodi di chiamata che ha causato l'eccezione, consentendo di individuare dove si è verificato l'errore nel codice.</xref:System.Exception.StackTrace%2A></span><span class="sxs-lookup"><span data-stu-id="eee9d-184">For example, the <xref:System.Exception.StackTrace%2A> property lists the called methods that led to the exception, helping you find where the error occurred in the code.</span></span> <span data-ttu-id="eee9d-185"><xref:System.Exception.Message%2A>Restituisce un messaggio che descrive l'eccezione.</xref:System.Exception.Message%2A></span><span class="sxs-lookup"><span data-stu-id="eee9d-185"><xref:System.Exception.Message%2A> returns a message that describes the exception.</span></span> <span data-ttu-id="eee9d-186"><xref:System.Exception.HelpLink%2A>Restituisce un collegamento a un file della Guida associato.</xref:System.Exception.HelpLink%2A></span><span class="sxs-lookup"><span data-stu-id="eee9d-186"><xref:System.Exception.HelpLink%2A> returns a link to an associated Help file.</span></span> <span data-ttu-id="eee9d-187"><xref:System.Exception.InnerException%2A>Restituisce il `Exception` oggetto che ha causato l'eccezione corrente oppure restituisce `Nothing` se è presente alcun originale `Exception`.</xref:System.Exception.InnerException%2A></span><span class="sxs-lookup"><span data-stu-id="eee9d-187"><xref:System.Exception.InnerException%2A> returns the `Exception` object that caused the current exception, or it returns `Nothing` if there is no original `Exception`.</span></span>  
  
## <a name="considerations-when-using-a-trycatch-statement"></a><span data-ttu-id="eee9d-188">Considerazioni sull'utilizzo di un blocco Try... Catch (istruzione)</span><span class="sxs-lookup"><span data-stu-id="eee9d-188">Considerations When Using a Try…Catch Statement</span></span>  
 <span data-ttu-id="eee9d-189">Utilizzare un `Try…Catch` istruzione solo per segnalare la presenza di eventi anomali o imprevisti.</span><span class="sxs-lookup"><span data-stu-id="eee9d-189">Use a `Try…Catch` statement only to signal the occurrence of unusual or unanticipated program events.</span></span> <span data-ttu-id="eee9d-190">Le cause includono quanto segue:</span><span class="sxs-lookup"><span data-stu-id="eee9d-190">Reasons for this include the following:</span></span>  
  
-   <span data-ttu-id="eee9d-191">Intercettare le eccezioni in fase di esecuzione comporta un sovraccarico aggiuntivo e potrebbero essere più lento rispetto alla verifica preliminare per evitare le eccezioni.</span><span class="sxs-lookup"><span data-stu-id="eee9d-191">Catching exceptions at runtime creates additional overhead, and is likely to be slower than pre-checking to avoid exceptions.</span></span>  
  
-   <span data-ttu-id="eee9d-192">Se un `Catch` blocco non viene gestito correttamente, l'eccezione potrebbe non essere segnalata correttamente agli utenti.</span><span class="sxs-lookup"><span data-stu-id="eee9d-192">If a `Catch` block is not handled correctly, the exception might not be reported correctly to users.</span></span>  
  
-   <span data-ttu-id="eee9d-193">Gestione delle eccezioni rende più complesso un programma.</span><span class="sxs-lookup"><span data-stu-id="eee9d-193">Exception handling makes a program more complex.</span></span>  
  
 <span data-ttu-id="eee9d-194">Non è sempre necessario un `Try…Catch` istruzione per verificare la presenza di una condizione che è probabile che si verifichi.</span><span class="sxs-lookup"><span data-stu-id="eee9d-194">You do not always need a `Try…Catch` statement to check for a condition that is likely to occur.</span></span> <span data-ttu-id="eee9d-195">Nell'esempio seguente verifica l'esistenza di un file prima di tentare di aprirlo.</span><span class="sxs-lookup"><span data-stu-id="eee9d-195">The following example checks whether a file exists before trying to open it.</span></span> <span data-ttu-id="eee9d-196">Questo riduce la necessità di rilevare un'eccezione generata dal <xref:System.IO.File.OpenText%2A>(metodo).</xref:System.IO.File.OpenText%2A></span><span class="sxs-lookup"><span data-stu-id="eee9d-196">This reduces the need for catching an exception thrown by the <xref:System.IO.File.OpenText%2A> method.</span></span>  
  
 <span data-ttu-id="eee9d-197">[!code-vb[VbVbalrStatements&#94;](../../../visual-basic/language-reference/error-messages/codesnippet/VisualBasic/try-catch-finally-statement_1.vb)]</span><span class="sxs-lookup"><span data-stu-id="eee9d-197">[!code-vb[VbVbalrStatements#94](../../../visual-basic/language-reference/error-messages/codesnippet/VisualBasic/try-catch-finally-statement_1.vb)]</span></span>  
  
 <span data-ttu-id="eee9d-198">Assicurarsi che il codice `Catch` blocchi possono segnalare correttamente le eccezioni per gli utenti, tramite accesso thread-safe o messaggi appropriati.</span><span class="sxs-lookup"><span data-stu-id="eee9d-198">Ensure that code in `Catch` blocks can properly report exceptions to users, whether through thread-safe logging or appropriate messages.</span></span> <span data-ttu-id="eee9d-199">In caso contrario, le eccezioni potrebbero rimanere sconosciute.</span><span class="sxs-lookup"><span data-stu-id="eee9d-199">Otherwise, exceptions might remain unknown.</span></span>  
  
## <a name="async-methods"></a><span data-ttu-id="eee9d-200">Metodi asincroni</span><span class="sxs-lookup"><span data-stu-id="eee9d-200">Async Methods</span></span>  
 <span data-ttu-id="eee9d-201">Se si contrassegna un metodo con il [Async](../../../visual-basic/language-reference/modifiers/async.md) modificatore, è possibile utilizzare il [Await](../../../visual-basic/language-reference/operators/await-operator.md) operatore nel metodo.</span><span class="sxs-lookup"><span data-stu-id="eee9d-201">If you mark a method with the [Async](../../../visual-basic/language-reference/modifiers/async.md) modifier, you can use the [Await](../../../visual-basic/language-reference/operators/await-operator.md) operator in the method.</span></span> <span data-ttu-id="eee9d-202">Un'istruzione con il `Await` operatore sospende l'esecuzione del metodo fino al completamento dell'attività attesa.</span><span class="sxs-lookup"><span data-stu-id="eee9d-202">A statement with the `Await` operator suspends execution of the method until the awaited task completes.</span></span> <span data-ttu-id="eee9d-203">L'attività rappresenta il lavoro attualmente in fase di esecuzione.</span><span class="sxs-lookup"><span data-stu-id="eee9d-203">The task represents ongoing work.</span></span> <span data-ttu-id="eee9d-204">Quando l'attività che è associato il `Await` operatore termina, riprende l'esecuzione nello stesso metodo.</span><span class="sxs-lookup"><span data-stu-id="eee9d-204">When the task that's associated with the `Await` operator finishes, execution resumes in the same method.</span></span> <span data-ttu-id="eee9d-205">Per ulteriori informazioni, vedere [flusso di controllo in programmi asincroni](../../../visual-basic/programming-guide/concepts/async/control-flow-in-async-programs.md).</span><span class="sxs-lookup"><span data-stu-id="eee9d-205">For more information, see [Control Flow in Async Programs](../../../visual-basic/programming-guide/concepts/async/control-flow-in-async-programs.md).</span></span>  
  
 <span data-ttu-id="eee9d-206">Un'attività restituita da un metodo asincrono può terminare con uno stato di errore, che indica che è stata completata a causa di un'eccezione non gestita.</span><span class="sxs-lookup"><span data-stu-id="eee9d-206">A task returned by an Async method may end in a faulted state, indicating that it completed due to an unhandled exception.</span></span> <span data-ttu-id="eee9d-207">Un'attività può inoltre terminare in uno stato annullato, che comporta un `OperationCanceledException` generata fuori l'espressione await.</span><span class="sxs-lookup"><span data-stu-id="eee9d-207">A task may also end in a canceled state, which results in an `OperationCanceledException` being thrown out of the await expression.</span></span> <span data-ttu-id="eee9d-208">Per entrambi i tipi di eccezione, inserire il `Await` espressione associata all'attività in un `Try` bloccare e rilevare l'eccezione nel `Catch` blocco.</span><span class="sxs-lookup"><span data-stu-id="eee9d-208">To catch either type of exception, place the `Await` expression that's associated with the task in a `Try` block, and catch the exception in the `Catch` block.</span></span> <span data-ttu-id="eee9d-209">Viene fornito un esempio più avanti in questo argomento.</span><span class="sxs-lookup"><span data-stu-id="eee9d-209">An example is provided later in this topic.</span></span>  
  
 <span data-ttu-id="eee9d-210">Un'attività può essere in uno stato di errore in quanto più eccezioni sono stati responsabili per il relativo stato di errore.</span><span class="sxs-lookup"><span data-stu-id="eee9d-210">A task can be in a faulted state because multiple exceptions were responsible for its faulting.</span></span> <span data-ttu-id="eee9d-211">Ad esempio, l'attività potrebbe essere il risultato di una chiamata a <xref:System.Threading.Tasks.Task.WhenAll%2A?displayProperty=fullName>.</xref:System.Threading.Tasks.Task.WhenAll%2A?displayProperty=fullName></span><span class="sxs-lookup"><span data-stu-id="eee9d-211">For example, the task might be the result of a call to <xref:System.Threading.Tasks.Task.WhenAll%2A?displayProperty=fullName>.</span></span> <span data-ttu-id="eee9d-212">Quando si attende tale attività, l'eccezione rilevata è solo una delle eccezioni e non è possibile prevedere quale eccezione verrà intercettata.</span><span class="sxs-lookup"><span data-stu-id="eee9d-212">When you await such a task, the caught exception is only one of the exceptions, and you can't predict which exception will be caught.</span></span> <span data-ttu-id="eee9d-213">Viene fornito un esempio più avanti in questo argomento.</span><span class="sxs-lookup"><span data-stu-id="eee9d-213">An example is provided later in this topic.</span></span>  
  
 <span data-ttu-id="eee9d-214">Un `Await` espressione non può essere all'interno di un `Catch` blocco o `Finally` blocco.</span><span class="sxs-lookup"><span data-stu-id="eee9d-214">An `Await` expression can't be inside a `Catch` block or `Finally` block.</span></span>  
  
## <a name="iterators"></a><span data-ttu-id="eee9d-215">Iteratori</span><span class="sxs-lookup"><span data-stu-id="eee9d-215">Iterators</span></span>  
 <span data-ttu-id="eee9d-216">Una funzione iteratore o `Get` della funzione di accesso esegue un'iterazione personalizzata su una raccolta.</span><span class="sxs-lookup"><span data-stu-id="eee9d-216">An iterator function or `Get` accessor performs a custom iteration over a collection.</span></span> <span data-ttu-id="eee9d-217">Un iteratore utilizza un [Yield](../../../visual-basic/language-reference/statements/yield-statement.md) istruzione per la restituzione di ogni elemento della raccolta uno alla volta.</span><span class="sxs-lookup"><span data-stu-id="eee9d-217">An iterator uses a [Yield](../../../visual-basic/language-reference/statements/yield-statement.md) statement to return each element of the collection one at a time.</span></span> <span data-ttu-id="eee9d-218">Per chiamare una funzione iteratore un [For Each... Istruzione successiva](../../../visual-basic/language-reference/statements/for-each-next-statement.md).</span><span class="sxs-lookup"><span data-stu-id="eee9d-218">You call an iterator function by using a [For Each...Next Statement](../../../visual-basic/language-reference/statements/for-each-next-statement.md).</span></span>  
  
 <span data-ttu-id="eee9d-219">Oggetto `Yield` istruzione può essere contenuta in un `Try` blocco.</span><span class="sxs-lookup"><span data-stu-id="eee9d-219">A `Yield` statement can be inside a `Try` block.</span></span> <span data-ttu-id="eee9d-220">Oggetto `Try` blocco che contiene un `Yield` istruzione possono essere presenti `Catch` si blocca e può avere un `Finally` blocco.</span><span class="sxs-lookup"><span data-stu-id="eee9d-220">A `Try` block that contains a `Yield` statement can have `Catch` blocks, and can have a `Finally` block.</span></span> <span data-ttu-id="eee9d-221">Vedere la sezione "provare a blocchi in Visual Basic" di [iteratori](http://msdn.microsoft.com/library/f45331db-d595-46ec-9142-551d3d1eb1a7) per un esempio.</span><span class="sxs-lookup"><span data-stu-id="eee9d-221">See the "Try Blocks in Visual Basic" section of [Iterators](http://msdn.microsoft.com/library/f45331db-d595-46ec-9142-551d3d1eb1a7) for an example.</span></span>  
  
 <span data-ttu-id="eee9d-222">Oggetto `Yield` istruzione non può essere all'interno di un `Catch` blocco o un `Finally` blocco.</span><span class="sxs-lookup"><span data-stu-id="eee9d-222">A `Yield` statement cannot be inside a `Catch` block or a `Finally` block.</span></span>  
  
 <span data-ttu-id="eee9d-223">Se il `For Each` corpo (all'esterno della funzione iteratore) genera un'eccezione, un `Catch` blocco nella funzione iteratore non viene eseguita, ma un `Finally` try nella funzione iteratore.</span><span class="sxs-lookup"><span data-stu-id="eee9d-223">If the `For Each` body (outside of the iterator function) throws an exception, a `Catch` block in the iterator function is not executed, but a `Finally` block in the iterator function is executed.</span></span> <span data-ttu-id="eee9d-224">Oggetto `Catch` blocco all'interno di una funzione iteratore intercetta solo le eccezioni che si verificano all'interno della funzione iteratore.</span><span class="sxs-lookup"><span data-stu-id="eee9d-224">A `Catch` block inside an iterator function catches only exceptions that occur inside the iterator function.</span></span>  
  
## <a name="partial-trust-situations"></a><span data-ttu-id="eee9d-225">Situazioni di attendibilità parziale</span><span class="sxs-lookup"><span data-stu-id="eee9d-225">Partial-Trust Situations</span></span>  
 <span data-ttu-id="eee9d-226">In situazioni di attendibilità parziale, ad esempio un'applicazione ospitata in una condivisione di rete, `Try...Catch...Finally` non intercetta le eccezioni di sicurezza che si verificano prima che venga richiamato il metodo che contiene la chiamata.</span><span class="sxs-lookup"><span data-stu-id="eee9d-226">In partial-trust situations, such as an application hosted on a network share, `Try...Catch...Finally` does not catch security exceptions that occur before the method that contains the call is invoked.</span></span> <span data-ttu-id="eee9d-227">L'esempio seguente, quando si inserisce in una condivisione server ed eseguita da lì, produce l'errore "System.Security.SecurityException: richiesta non riuscita."</span><span class="sxs-lookup"><span data-stu-id="eee9d-227">The following example, when you put it on a server share and run from there, produces the error "System.Security.SecurityException: Request Failed."</span></span> <span data-ttu-id="eee9d-228">Per ulteriori informazioni sulle eccezioni di sicurezza, vedere la <xref:System.Security.SecurityException>classe.</xref:System.Security.SecurityException></span><span class="sxs-lookup"><span data-stu-id="eee9d-228">For more information about security exceptions, see the <xref:System.Security.SecurityException> class.</span></span>  
  
 <span data-ttu-id="eee9d-229">[!code-vb[&#85; VbVbalrStatements](../../../visual-basic/language-reference/error-messages/codesnippet/VisualBasic/try-catch-finally-statement_2.vb)]</span><span class="sxs-lookup"><span data-stu-id="eee9d-229">[!code-vb[VbVbalrStatements#85](../../../visual-basic/language-reference/error-messages/codesnippet/VisualBasic/try-catch-finally-statement_2.vb)]</span></span>  
  
 <span data-ttu-id="eee9d-230">In una situazione di attendibilità parziale di questo tipo, è necessario inserire il `Process.Start` istruzione in un oggetto separato `Sub`.</span><span class="sxs-lookup"><span data-stu-id="eee9d-230">In such a partial-trust situation, you have to put the `Process.Start` statement in a separate `Sub`.</span></span> <span data-ttu-id="eee9d-231">La chiamata iniziale per il `Sub` avrà esito negativo.</span><span class="sxs-lookup"><span data-stu-id="eee9d-231">The initial call to the `Sub` will fail.</span></span> <span data-ttu-id="eee9d-232">In questo modo `Try...Catch` per intercettare, prima di `Sub` contenente `Process.Start` viene avviato e ha causato l'eccezione di sicurezza.</span><span class="sxs-lookup"><span data-stu-id="eee9d-232">This enables `Try...Catch` to catch it before the `Sub` that contains `Process.Start` is started and the security exception produced.</span></span>  
  
## <a name="example"></a><span data-ttu-id="eee9d-233">Esempio</span><span class="sxs-lookup"><span data-stu-id="eee9d-233">Example</span></span>  
 <span data-ttu-id="eee9d-234">Nell'esempio seguente viene illustrata la struttura del `Try...Catch...Finally` istruzione.</span><span class="sxs-lookup"><span data-stu-id="eee9d-234">The following example illustrates the structure of the `Try...Catch...Finally` statement.</span></span>  
  
 <span data-ttu-id="eee9d-235">[!code-vb[VbVbalrStatements&#86;](../../../visual-basic/language-reference/error-messages/codesnippet/VisualBasic/try-catch-finally-statement_3.vb)]</span><span class="sxs-lookup"><span data-stu-id="eee9d-235">[!code-vb[VbVbalrStatements#86](../../../visual-basic/language-reference/error-messages/codesnippet/VisualBasic/try-catch-finally-statement_3.vb)]</span></span>  
  
## <a name="example"></a><span data-ttu-id="eee9d-236">Esempio</span><span class="sxs-lookup"><span data-stu-id="eee9d-236">Example</span></span>  
 <span data-ttu-id="eee9d-237">Nell'esempio seguente, il `CreateException` genererà un `NullReferenceException`.</span><span class="sxs-lookup"><span data-stu-id="eee9d-237">In the following example, the `CreateException` method throws a `NullReferenceException`.</span></span> <span data-ttu-id="eee9d-238">Il codice che genera l'eccezione non si trova in un `Try` blocco.</span><span class="sxs-lookup"><span data-stu-id="eee9d-238">The code that generates the exception is not in a `Try` block.</span></span> <span data-ttu-id="eee9d-239">Pertanto, il `CreateException` metodo gestisce l'eccezione.</span><span class="sxs-lookup"><span data-stu-id="eee9d-239">Therefore, the `CreateException` method does not handle the exception.</span></span> <span data-ttu-id="eee9d-240">Il `RunSample` metodo gestisce l'eccezione perché la chiamata al `CreateException` metodo si trova in un `Try` blocco.</span><span class="sxs-lookup"><span data-stu-id="eee9d-240">The `RunSample` method does handle the exception because the call to the `CreateException` method is in a `Try` block.</span></span>  
  
 <span data-ttu-id="eee9d-241">L'esempio include `Catch` istruzioni per diversi tipi di eccezioni, ordinate dalla più specifica alla più generale.</span><span class="sxs-lookup"><span data-stu-id="eee9d-241">The example includes `Catch` statements for several types of exceptions, ordered from the most specific to the most general.</span></span>  
  
 <span data-ttu-id="eee9d-242">[!code-vb[VbVbalrStatements&#91;](../../../visual-basic/language-reference/error-messages/codesnippet/VisualBasic/try-catch-finally-statement_4.vb)]</span><span class="sxs-lookup"><span data-stu-id="eee9d-242">[!code-vb[VbVbalrStatements#91](../../../visual-basic/language-reference/error-messages/codesnippet/VisualBasic/try-catch-finally-statement_4.vb)]</span></span>  
  
## <a name="example"></a><span data-ttu-id="eee9d-243">Esempio</span><span class="sxs-lookup"><span data-stu-id="eee9d-243">Example</span></span>  
 <span data-ttu-id="eee9d-244">Nell'esempio seguente viene illustrato come utilizzare un `Catch When` istruzione per filtrare un'espressione condizionale.</span><span class="sxs-lookup"><span data-stu-id="eee9d-244">The following example shows how to use a `Catch When` statement to filter on a conditional expression.</span></span> <span data-ttu-id="eee9d-245">Se l'espressione condizionale restituisce `True`, il codice di `Catch` bloccare l'esecuzione.</span><span class="sxs-lookup"><span data-stu-id="eee9d-245">If the conditional expression evaluates to `True`, the code in the `Catch` block runs.</span></span>  
  
 <span data-ttu-id="eee9d-246">[!code-vb[VbVbalrStatements&#92;](../../../visual-basic/language-reference/error-messages/codesnippet/VisualBasic/try-catch-finally-statement_5.vb)]</span><span class="sxs-lookup"><span data-stu-id="eee9d-246">[!code-vb[VbVbalrStatements#92](../../../visual-basic/language-reference/error-messages/codesnippet/VisualBasic/try-catch-finally-statement_5.vb)]</span></span>  
  
## <a name="example"></a><span data-ttu-id="eee9d-247">Esempio</span><span class="sxs-lookup"><span data-stu-id="eee9d-247">Example</span></span>  
 <span data-ttu-id="eee9d-248">Nell'esempio seguente è presente un `Try…Catch` istruzione contenuta in un `Try` blocco.</span><span class="sxs-lookup"><span data-stu-id="eee9d-248">The following example has a `Try…Catch` statement that is contained in a `Try` block.</span></span> <span data-ttu-id="eee9d-249">L'eccezione interna `Catch` blocco genera un'eccezione che ha il `InnerException` impostata sull'eccezione originale.</span><span class="sxs-lookup"><span data-stu-id="eee9d-249">The inner `Catch` block throws an exception that has its `InnerException` property set to the original exception.</span></span> <span data-ttu-id="eee9d-250">Esterna `Catch` blocco segnala la propria eccezione e l'eccezione interna.</span><span class="sxs-lookup"><span data-stu-id="eee9d-250">The outer `Catch` block reports its own exception and the inner exception.</span></span>  
  
 <span data-ttu-id="eee9d-251">[!code-vb[&#93; VbVbalrStatements](../../../visual-basic/language-reference/error-messages/codesnippet/VisualBasic/try-catch-finally-statement_6.vb)]</span><span class="sxs-lookup"><span data-stu-id="eee9d-251">[!code-vb[VbVbalrStatements#93](../../../visual-basic/language-reference/error-messages/codesnippet/VisualBasic/try-catch-finally-statement_6.vb)]</span></span>  
  
## <a name="example"></a><span data-ttu-id="eee9d-252">Esempio</span><span class="sxs-lookup"><span data-stu-id="eee9d-252">Example</span></span>  
 <span data-ttu-id="eee9d-253">L'esempio seguente illustra la gestione delle eccezioni per i metodi asincroni.</span><span class="sxs-lookup"><span data-stu-id="eee9d-253">The following example illustrates exception handling for async methods.</span></span> <span data-ttu-id="eee9d-254">Per rilevare un'eccezione che si applica a un'attività asincrona, il `Await` l'espressione ha un `Try` blocco del chiamante e l'eccezione viene rilevata nel `Catch` blocco.</span><span class="sxs-lookup"><span data-stu-id="eee9d-254">To catch an exception that applies to an async task, the `Await` expression is in a `Try` block of the caller, and the exception is caught in the `Catch` block.</span></span>  
  
 <span data-ttu-id="eee9d-255">Rimuovere il commento dalla riga `Throw New Exception` nell'esempio per illustrare la gestione delle eccezioni.</span><span class="sxs-lookup"><span data-stu-id="eee9d-255">Uncomment the `Throw New Exception` line in the example to demonstrate exception handling.</span></span> <span data-ttu-id="eee9d-256">L'eccezione viene rilevata nel `Catch` blocco, l'attività `IsFaulted` è impostata su `True`e l'attività `Exception.InnerException` proprietà è impostata sull'eccezione.</span><span class="sxs-lookup"><span data-stu-id="eee9d-256">The exception is caught in the `Catch` block, the task's `IsFaulted` property is set to `True`, and the task's `Exception.InnerException` property is set to the exception.</span></span>  
  
 <span data-ttu-id="eee9d-257">Rimuovere il commento di `Throw New OperationCancelledException` riga per illustrare ciò che accade quando si annulla un processo asincrono.</span><span class="sxs-lookup"><span data-stu-id="eee9d-257">Uncomment the `Throw New OperationCancelledException` line to demonstrate what happens when you cancel an asynchronous process.</span></span> <span data-ttu-id="eee9d-258">L'eccezione viene rilevata nel `Catch` blocco e l'attività `IsCanceled` è impostata su `True`.</span><span class="sxs-lookup"><span data-stu-id="eee9d-258">The exception is caught in the `Catch` block, and the task's `IsCanceled` property is set to `True`.</span></span> <span data-ttu-id="eee9d-259">Tuttavia, in alcune condizioni sono validi per questo esempio, `IsFaulted` è impostato su `True` e `IsCanceled` è impostato su `False`.</span><span class="sxs-lookup"><span data-stu-id="eee9d-259">However, under some conditions that don't apply to this example, `IsFaulted` is set to `True` and `IsCanceled` is set to `False`.</span></span>  
  
 <span data-ttu-id="eee9d-260">[!code-vb[csAsyncExceptions n.&1;](../../../csharp/language-reference/keywords/codesnippet/VisualBasic/try-catch-finally-statement_7.vb)]</span><span class="sxs-lookup"><span data-stu-id="eee9d-260">[!code-vb[csAsyncExceptions#1](../../../csharp/language-reference/keywords/codesnippet/VisualBasic/try-catch-finally-statement_7.vb)]</span></span>  
  
## <a name="example"></a><span data-ttu-id="eee9d-261">Esempio</span><span class="sxs-lookup"><span data-stu-id="eee9d-261">Example</span></span>  
 <span data-ttu-id="eee9d-262">Il seguente esempio illustra la gestione delle eccezioni dove più attività possono restituire più eccezioni.</span><span class="sxs-lookup"><span data-stu-id="eee9d-262">The following example illustrates exception handling where multiple tasks can result in multiple exceptions.</span></span> <span data-ttu-id="eee9d-263">Il `Try` blocco ha il `Await` espressione per l'attività che <xref:System.Threading.Tasks.Task.WhenAll%2A?displayProperty=fullName>restituito.</xref:System.Threading.Tasks.Task.WhenAll%2A?displayProperty=fullName></span><span class="sxs-lookup"><span data-stu-id="eee9d-263">The `Try` block has the `Await` expression for the task that <xref:System.Threading.Tasks.Task.WhenAll%2A?displayProperty=fullName> returned.</span></span> <span data-ttu-id="eee9d-264">L'attività viene completata quando le tre attività a cui <xref:System.Threading.Tasks.Task.WhenAll%2A?displayProperty=fullName>viene applicato sono state completate.</xref:System.Threading.Tasks.Task.WhenAll%2A?displayProperty=fullName></span><span class="sxs-lookup"><span data-stu-id="eee9d-264">The task is complete when the three tasks to which <xref:System.Threading.Tasks.Task.WhenAll%2A?displayProperty=fullName> is applied are complete.</span></span>  
  
 <span data-ttu-id="eee9d-265">Ognuna delle tre attività genera un'eccezione.</span><span class="sxs-lookup"><span data-stu-id="eee9d-265">Each of the three tasks causes an exception.</span></span> <span data-ttu-id="eee9d-266">Il `Catch` blocco scorre le eccezioni, che si trovano nella `Exception.InnerExceptions` proprietà dell'attività che `Task.WhenAll` restituito.</span><span class="sxs-lookup"><span data-stu-id="eee9d-266">The `Catch` block iterates through the exceptions, which are found in the `Exception.InnerExceptions` property of the task that `Task.WhenAll` returned.</span></span>  
  
 <span data-ttu-id="eee9d-267">[!code-vb[csAsyncExceptions n.&3;](../../../csharp/language-reference/keywords/codesnippet/VisualBasic/try-catch-finally-statement_8.vb)]</span><span class="sxs-lookup"><span data-stu-id="eee9d-267">[!code-vb[csAsyncExceptions#3](../../../csharp/language-reference/keywords/codesnippet/VisualBasic/try-catch-finally-statement_8.vb)]</span></span>  
  
## <a name="see-also"></a><span data-ttu-id="eee9d-268">Vedere anche</span><span class="sxs-lookup"><span data-stu-id="eee9d-268">See Also</span></span>  
 <span data-ttu-id="eee9d-269"><xref:Microsoft.VisualBasic.Information.Err%2A></xref:Microsoft.VisualBasic.Information.Err%2A></span><span class="sxs-lookup"><span data-stu-id="eee9d-269"><xref:Microsoft.VisualBasic.Information.Err%2A></span></span>   
 <span data-ttu-id="eee9d-270"><xref:System.Exception></xref:System.Exception></span><span class="sxs-lookup"><span data-stu-id="eee9d-270"><xref:System.Exception></span></span>   
<span data-ttu-id="eee9d-271"> [Exit (istruzione)](../../../visual-basic/language-reference/statements/exit-statement.md) </span><span class="sxs-lookup"><span data-stu-id="eee9d-271"> [Exit Statement](../../../visual-basic/language-reference/statements/exit-statement.md) </span></span>  
<span data-ttu-id="eee9d-272"> [Istruzione On Error](../../../visual-basic/language-reference/statements/on-error-statement.md) </span><span class="sxs-lookup"><span data-stu-id="eee9d-272"> [On Error Statement](../../../visual-basic/language-reference/statements/on-error-statement.md) </span></span>  
<span data-ttu-id="eee9d-273"> [Procedure consigliate per l'utilizzo di frammenti di codice](https://docs.microsoft.com/visualstudio/ide/best-practices-for-using-code-snippets) </span><span class="sxs-lookup"><span data-stu-id="eee9d-273"> [Best Practices for Using Code Snippets](https://docs.microsoft.com/visualstudio/ide/best-practices-for-using-code-snippets) </span></span>  
<span data-ttu-id="eee9d-274"> [Gestione delle eccezioni](https://msdn.microsoft.com/library/dd997415) </span><span class="sxs-lookup"><span data-stu-id="eee9d-274"> [Exception Handling](https://msdn.microsoft.com/library/dd997415) </span></span>  
<span data-ttu-id="eee9d-275"> [Istruzione Throw](../../../visual-basic/language-reference/statements/throw-statement.md)</span><span class="sxs-lookup"><span data-stu-id="eee9d-275"> [Throw Statement](../../../visual-basic/language-reference/statements/throw-statement.md)</span></span>
